<?xml version="1.0"?>
<robot name="ro-02-auer">

  <link name="base_link">
    <visual>
      <geometry>
         <box size="0.3 0.3 0.6"/>
      </geometry>
      <material name="blue">
        <color rgba="0 0 0.9 1"/>
      </material>
    </visual>
  </link>

  <link name="head">
    <visual>
      <origin xyz="0 0 0.11"/>
      <geometry>
        <box size="0.1 0.1 0.2"/>
      </geometry>
      <material name="white">
        <color rgba="1 1 1 1"/>
      </material>
    </visual>
  </link>

  <joint name="head_to_base" type="fixed">
    <parent link="base_link"/>
    <child link="head"/>
    <origin xyz="0 0 0.3"/>
  </joint>
   
  <link name="wheel">
    <visual>
      <origin rpy="0 1.57075 0" xyz="0 0 -0.21"/>
      <geometry>
        <cylinder length="0.5" radius="0.2"/>
      </geometry>
      <material name="blue">
        <color rgba="0 0 0.9 1"/>
      </material>
    </visual>
  </link>

  <joint name="wheel_to_base" type="fixed">
    <parent link="base_link"/>
    <child link="wheel"/>
    <origin xyz="0 0 -0.3"/>
  </joint>

  <link name="arm_right">
    <visual>
      <origin xyz="0.05 0 -0.2"/>
      <geometry>
        <box size="0.05 0.05 0.5"/>
      </geometry>
      <material name="white">
        <color rgba="1 1 1 1"/>
      </material>
    </visual>
  </link>

  <joint name="arm_right_to_base" type="fixed">
    <parent link="base_link"/>
    <child link="arm_right"/>
    <origin xyz="0.15 0 0.2"/>
  </joint>

  <link name="arm_left">
    <visual>
      <origin xyz="-0.05 0 -0.2"/>
      <geometry>
        <box size="0.05 0.05 0.5"/>
      </geometry>
      <material name="white">
        <color rgba="1 1 1 1"/>
      </material>
    </visual>
  </link>

  <joint name="arm_left_to_base" type="continuous">
    <parent link="base_link"/>
    <child link="arm_left"/>
    <axis xyz="1 1 1"/>
    <origin xyz="-0.15 0 0.2"/>
  </joint>
</robot>
